Workbook
Name IQ_CH: 110000
Name IQ_CQ: 5000
Name IQ_CY: 10000
Name IQ_DAILY: 500000
Name IQ_FH: 100000
Name IQ_FQ: 500
Name IQ_FY: 1000
Name IQ_LTM: 2000
Name IQ_MONTH: 15000
Name IQ_NTM: 6000
Name IQ_WEEK: 50000
Name IQ_YTD: 3000
Name UPDATE: 'Data Sheet'!$E$1

Sheet Historical FS
B2: ="Historical Financial Statement - "&'Data Sheet'!B1 -> Historical Financial Statement - ITC LTD
B3: Years | C3: ='Data Sheet'!B16 -> 42825 | D3: ='Data Sheet'!C16 -> 43190 | E3: ='Data Sheet'!D16 -> 43555 | F3: ='Data Sheet'!E16 -> 43921 | G3: ='Data Sheet'!F16 -> 44286 | H3: ='Data Sheet'!G16 -> 44651 | I3: ='Data Sheet'!H16 -> 45016 | J3: ='Data Sheet'!I16 -> 45382 | ... L3: ='Data Sheet'!K16 -> 46112 | M3: LTM
A5: # | B5: Income Statement
B6: Sales | C6: =IFERROR('Data Sheet'!B17,0) -> 42767.6 | D6: =IFERROR('Data Sheet'!C17,0) -> 43448.94 | E6: =IFERROR('Data Sheet'!D17,0) -> 48339.58 | F6: =IFERROR('Data Sheet'!E17,0) -> 49387.7 | G6: =IFERROR('Data Sheet'!F17,0) -> 49257.45 | H6: =IFERROR('Data Sheet'!G17,0) -> 60644.54 | I6: =IFERROR('Data Sheet'!H17,0) -> 70919.03 | J6: =IFERROR('Data Sheet'!I17,0) -> 67931.94 | ... L6: =IFERROR('Data Sheet'!K17,0) -> 78868.4 | M6: =IFERROR(SUM('Data Sheet'!H42:K42),0) -> 76487.98
B7: Sales Growth | C7: - | D7: =D6/C6-1 -> 0.015931219 | E7: =E6/D6-1 -> 0.11256063 | F7: =F6/E6-1 -> 0.021682439 | G7: =G6/F6-1 -> -0.0026372963 | H7: =H6/G6-1 -> 0.23117498 | I7: =I6/H6-1 -> 0.16942152 | J7: =J6/I6-1 -> -0.042119724 | K7: =K6/J6-1 -> 0.10880596 | ... M7: =M6/L6-1 -> -0.030182177
B9: COGS | C9: =IFERROR(SUM('Data Sheet'!B18,'Data Sheet'!B20:B22)-1*'Data Sheet'!B19,0) -> 21949.12 | D9: =IFERROR(SUM('Data Sheet'!C18,'Data Sheet'!C20:C22)-1*'Data Sheet'!C19,0) -> 21967.5 | E9: =IFERROR(SUM('Data Sheet'!D18,'Data Sheet'!D20:D22)-1*'Data Sheet'!D19,0) -> 24215.95 | F9: =IFERROR(SUM('Data Sheet'!E18,'Data Sheet'!E20:E22)-1*'Data Sheet'!E19,0) -> 24330.4 | G9: =IFERROR(SUM('Data Sheet'!F18,'Data Sheet'!F20:F22)-1*'Data Sheet'!F19,0) -> 26881.51 | H9: =IFERROR(SUM('Data Sheet'!G18,'Data Sheet'!G20:G22)-1*'Data Sheet'!G19,0) -> 34053.06 | I9: =IFERROR(SUM('Data Sheet'!H18,'Data Sheet'!H20:H22)-1*'Data Sheet'!H19,0) -> 38302.13 | J9: =IFERROR(SUM('Data Sheet'!I18,'Data Sheet'!I20:I22)-1*'Data Sheet'!I19,0) -> 35665.99 | ... L9: =IFERROR(SUM('Data Sheet'!K18,'Data Sheet'!K20:K22)-1*'Data Sheet'!K19,0) -> 42859.57 | M9: =IFERROR(SUM('Data Sheet'!H43:K43),0) -> 50805.68
B10: COGS % Sales | C10: =C9/C6 -> 0.51321842 | D10: =D9/D6 -> 0.50559346 | E10: =E9/E6 -> 0.50095491 | F10: =F9/F6 -> 0.49264088 | G10: =G9/G6 -> 0.54573491 | H10: =H9/H6 -> 0.56151898 | I10: =I9/I6 -> 0.54008254 | J10: =J9/J6 -> 0.52502534 | ... M10: =M9/M6 -> 0.6642309
B12: Gross Profit | C12: =C6-C9 -> 20818.48 | D12: =D6-D9 -> 21481.44 | E12: =E6-E9 -> 24123.63 | F12: =F6-F9 -> 25057.3 | G12: =G6-G9 -> 22375.94 | H12: =H6-H9 -> 26591.48 | I12: =I6-I9 -> 32616.9 | J12: =J6-J9 -> 32265.95 | ... M12: =M6-M9 -> 25682.3
B13: Gross Margins | C13: =C12/C6 -> 0.48678158 | D13: =D12/D6 -> 0.49440654 | E13: =E12/E6 -> 0.49904509 | F13: =F12/F6 -> 0.50735912 | G13: =G12/G6 -> 0.45426509 | H13: =H12/H6 -> 0.43848102 | I13: =I12/I6 -> 0.45991746 | J13: =J12/J6 -> 0.47497466 | ... M13: =M12/M6 -> 0.3357691
B15: Selling & General Expenses | C15: =IFERROR(SUM('Data Sheet'!B23:B24),0) -> 5348.97 | D15: =IFERROR(SUM('Data Sheet'!C23:C24),0) -> 4960.85 | E15: =IFERROR(SUM('Data Sheet'!D23:D24),0) -> 5586.24 | F15: =IFERROR(SUM('Data Sheet'!E23:E24),0) -> 5713.76 | G15: =IFERROR(SUM('Data Sheet'!F23:F24),0) -> 5311.16 | H15: =IFERROR(SUM('Data Sheet'!G23:G24),0) -> 5968.33 | I15: =IFERROR(SUM('Data Sheet'!H23:H24),0) -> 6912.64 | J15: =IFERROR(SUM('Data Sheet'!I23:I24),0) -> 7078.42 | ... L15: =IFERROR(SUM('Data Sheet'!K23:K24),0) -> 8702.83
B16: S&G Exp % Sales | C16: =C15/C6 -> 0.12507061 | D16: =D15/D6 -> 0.11417655 | E16: =E15/E6 -> 0.11556244 | F16: =F15/F6 -> 0.11569196 | G16: =G15/G6 -> 0.1078245 | H16: =H15/H6 -> 0.09841496 | I16: =I15/I6 -> 0.097472286 | J16: =J15/J6 -> 0.1041987 | ... M16: =M15/M6 -> 0
B18: EBITDA | C18: =C12-C15 -> 15469.51 | D18: =D12-D15 -> 16520.59 | E18: =E12-E15 -> 18537.39 | F18: =F12-F15 -> 19343.54 | G18: =G12-G15 -> 17064.78 | H18: =H12-H15 -> 20623.15 | I18: =I12-I15 -> 25704.26 | J18: =J12-J15 -> 25187.53 | ... L18: =L12-L15 -> 27306 | M18: =IFERROR(SUM('Data Sheet'!H51:K51),0) -> 28245.88
B19: EBITDA Margins | C19: =C18/C6 -> 0.36171097 | D19: =D18/D6 -> 0.38022999 | E19: =E18/E6 -> 0.38348265 | F19: =F18/F6 -> 0.39166716 | G19: =G18/G6 -> 0.34644059 | H19: =H18/H6 -> 0.34006606 | I19: =I18/I6 -> 0.36244517 | J19: =J18/J6 -> 0.37077596 | ... M19: =M18/M6 -> 0.36928521
B21: Interest | C21: =IFERROR('Data Sheet'!B27,0) -> 49.03 | D21: =IFERROR('Data Sheet'!C27,0) -> 115.01 | E21: =IFERROR('Data Sheet'!D27,0) -> 71.4 | F21: =IFERROR('Data Sheet'!E27,0) -> 81.38 | G21: =IFERROR('Data Sheet'!F27,0) -> 57.97 | H21: =IFERROR('Data Sheet'!G27,0) -> 59.99 | I21: =IFERROR('Data Sheet'!H27,0) -> 77.77 | J21: =IFERROR('Data Sheet'!I27,0) -> 39.11 | ... L21: =IFERROR('Data Sheet'!K27,0) -> 85.17 | M21: =IFERROR(SUM('Data Sheet'!H46:K46),0) -> 108.48
B22: Interest % Sales | C22: =C21/C6 -> 0.0011464286 | D22: =D21/D6 -> 0.0026470151 | E22: =E21/E6 -> 0.0014770505 | F22: =F21/F6 -> 0.0016477787 | G22: =G21/G6 -> 0.0011768778 | H22: =H21/H6 -> 0.00098920694 | I22: =I21/I6 -> 0.0010966027 | J22: =J21/J6 -> 0.00057572329 | ... M22: =M21/M6 -> 0.0014182621
B24: Depreciation | C24: =IFERROR('Data Sheet'!B26,0) -> 1152.79 | D24: =IFERROR('Data Sheet'!C26,0) -> 1236.28 | E24: =IFERROR('Data Sheet'!D26,0) -> 1396.61 | F24: =IFERROR('Data Sheet'!E26,0) -> 1644.91 | G24: =IFERROR('Data Sheet'!F26,0) -> 1645.59 | H24: =IFERROR('Data Sheet'!G26,0) -> 1732.41 | I24: =IFERROR('Data Sheet'!H26,0) -> 1809.01 | J24: =IFERROR('Data Sheet'!I26,0) -> 1518.05 | ... L24: =IFERROR('Data Sheet'!K26,0) -> 1710.53 | M24: =IFERROR(SUM('Data Sheet'!H45:K45),0) -> 1715.3
B25: Depreciation%Sales | C25: =C24/C6 -> 0.026954751 | D25: =D24/D6 -> 0.028453629 | E25: =E24/E6 -> 0.028891645 | F25: =F24/F6 -> 0.033306066 | G25: =G24/G6 -> 0.033407941 | H25: =H24/H6 -> 0.028566628 | I25: =I24/I6 -> 0.025508104 | J25: =J24/J6 -> 0.022346631 | ... M25: =M24/M6 -> 0.022425746
B27: EBIT | C27: =IFERROR(C18-C24,0) -> 14316.72 | D27: =IFERROR(D18-D24,0) -> 15284.31 | E27: =IFERROR(E18-E24,0) -> 17140.78 | F27: =IFERROR(F18-F24,0) -> 17698.63 | G27: =IFERROR(G18-G24,0) -> 15419.19 | H27: =IFERROR(H18-H24,0) -> 18890.74 | I27: =IFERROR(I18-I24,0) -> 23895.25 | J27: =IFERROR(J18-J24,0) -> 23669.48 | ... M27: =IFERROR(M18-M24,0) -> 26530.58
B28: EBIT Margins | C28: =C27/C6 -> 0.33475622 | D28: =D27/D6 -> 0.35177636 | E28: =E27/E6 -> 0.354591 | F28: =F27/F6 -> 0.35836109 | G28: =G27/G6 -> 0.31303265 | H28: =H27/H6 -> 0.31149944 | I28: =I27/I6 -> 0.33693707 | J28: =J27/J6 -> 0.34842932 | ... M28: =M27/M6 -> 0.34685947
B30: Earnings Before Tax | C30: =IFERROR(C18-SUM(C24,C21),0) -> 14267.69 | D30: =IFERROR(D18-SUM(D24,D21),0) -> 15169.3 | E30: =IFERROR(E18-SUM(E24,E21),0) -> 17069.38 | F30: =IFERROR(F18-SUM(F24,F21),0) -> 17617.25 | G30: =IFERROR(G18-SUM(G24,G21),0) -> 15361.22 | H30: =IFERROR(H18-SUM(H24,H21),0) -> 18830.75 | I30: =IFERROR(I18-SUM(I24,I21),0) -> 23817.48 | J30: =IFERROR(J18-SUM(J24,J21),0) -> 23630.37 | ... M30: =IFERROR(M18-SUM(M24,M21),0) -> 26422.1
B31: EBT % Sales | C31: =C30/C6 -> 0.33360979 | D31: =D30/D6 -> 0.34912935 | E31: =E30/E6 -> 0.35311395 | F31: =F30/F6 -> 0.35671331 | G31: =G30/G6 -> 0.31185577 | H31: =H30/H6 -> 0.31051023 | I31: =I30/I6 -> 0.33584046 | J31: =J30/J6 -> 0.3478536 | ... M31: =M30/M6 -> 0.34544121
B33: Tax | C33: =IFERROR('Data Sheet'!B29,0) -> 5549.09 | D33: =IFERROR('Data Sheet'!C29,0) -> 5916.43 | E33: =IFERROR('Data Sheet'!D29,0) -> 6313.92 | F33: =IFERROR('Data Sheet'!E29,0) -> 4441.79 | G33: =IFERROR('Data Sheet'!F29,0) -> 4555.29 | H33: =IFERROR('Data Sheet'!G29,0) -> 5237.34 | I33: =IFERROR('Data Sheet'!H29,0) -> 6438.4 | J33: =IFERROR('Data Sheet'!I29,0) -> 6209.46 | ... L33: =IFERROR('Data Sheet'!K29,0) -> 7015.24 | M33: =IFERROR(SUM('Data Sheet'!H48:K48),0) -> 6582.7
B34: Effective Tax Rate | C34: =C33/C30 -> 0.38892701 | D34: =D33/D30 -> 0.39002657 | E34: =E33/E30 -> 0.36989744 | F34: =F33/F30 -> 0.25212732 | G34: =G33/G30 -> 0.29654481 | H34: =H33/H30 -> 0.278127 | I34: =I33/I30 -> 0.27032247 | J34: =J33/J30 -> 0.26277456 | ... M34: =M33/M30 -> 0.24913614
B36: Net Profit | C36: =IFERROR(C30-C33,0) -> 8718.6 | D36: =IFERROR(D30-D33,0) -> 9252.87 | E36: =IFERROR(E30-E33,0) -> 10755.46 | F36: =IFERROR(F30-F33,0) -> 13175.46 | G36: =IFERROR(G30-G33,0) -> 10805.93 | H36: =IFERROR(H30-H33,0) -> 13593.41 | I36: =IFERROR(I30-I33,0) -> 17379.08 | J36: =IFERROR(J30-J33,0) -> 17420.91 | ... M36: =IFERROR(M30-M33,0) -> 19839.4
B37: Net Margins | C37: =C36/C6 -> 0.20385993 | D37: =D36/D6 -> 0.21295963 | E37: =E36/E6 -> 0.222498 | F37: =F36/F6 -> 0.26677614 | G37: =G36/G6 -> 0.21937656 | H37: =H36/H6 -> 0.22414895 | I37: =I36/I6 -> 0.24505524 | J37: =J36/J6 -> 0.25644653 | ... M37: =M36/M6 -> 0.25937932
B39: No of Equity Shares | C39: =IFERROR('Data Sheet'!B93,0) -> 1214.74 | D39: =IFERROR('Data Sheet'!C93,0) -> 1220.43 | E39: =IFERROR('Data Sheet'!D93,0) -> 1225.86 | F39: =IFERROR('Data Sheet'!E93,0) -> 1229.22 | G39: =IFERROR('Data Sheet'!F93,0) -> 1230.88 | H39: =IFERROR('Data Sheet'!G93,0) -> 1232.33 | I39: =IFERROR('Data Sheet'!H93,0) -> 1242.8 | J39: =IFERROR('Data Sheet'!I93,0) -> 1248.47 | ... L39: =IFERROR('Data Sheet'!K93,0) -> 1252.95 | M39: =L39 -> 1252.95
B41: Earnings per Share | C41: =IFERROR(C36/C39,0) -> 7.1773384 | D41: =IFERROR(D36/D39,0) -> 7.5816475 | E41: =IFERROR(E36/E39,0) -> 8.7738078 | F41: =IFERROR(F36/F39,0) -> 10.718553 | G41: =IFERROR(G36/G39,0) -> 8.779028 | H41: =IFERROR(H36/H39,0) -> 11.030657 | I41: =IFERROR(I36/I39,0) -> 13.983811 | J41: =IFERROR(J36/J39,0) -> 13.953807 | ... M41: =IFERROR(M36/M39,0) -> 15.834151
B42: EPS Growth % | D42: =IFERROR(D41/C41-1,0) -> 0.056331341 | E42: =IFERROR(E41/D41-1,0) -> 0.15724291 | F42: =IFERROR(F41/E41-1,0) -> 0.22165353 | G42: =IFERROR(G41/F41-1,0) -> -0.18095028 | H42: =IFERROR(H41/G41-1,0) -> 0.25647821 | I42: =IFERROR(I41/H41-1,0) -> 0.26772234 | J42: =IFERROR(J41/I41-1,0) -> -0.0021455732 | K42: =IFERROR(K41/J41-1,0) -> -0.012152388 | ... M42: =IFERROR(M41/L41-1,0) -> 0.072686436
B44: Dividend per Share | C44: =IFERROR('Data Sheet'!B31/'Historical FS'!C39,0) -> 4.7500041 | D44: =IFERROR('Data Sheet'!C31/'Historical FS'!D39,0) -> 5.1499963 | E44: =IFERROR('Data Sheet'!D31/'Historical FS'!E39,0) -> 5.7500041 | F44: =IFERROR('Data Sheet'!E31/'Historical FS'!F39,0) -> 10.149998 | G44: =IFERROR('Data Sheet'!F31/'Historical FS'!G39,0) -> 10.75 | H44: =IFERROR('Data Sheet'!G31/'Historical FS'!H39,0) -> 11.500004 | I44: =IFERROR('Data Sheet'!H31/'Historical FS'!I39,0) -> 15.5 | J44: =IFERROR('Data Sheet'!I31/'Historical FS'!J39,0) -> 13.749998 | ... M44: =IFERROR('Data Sheet'!L31/'Historical FS'!M39,0) -> 0
B45: Dividend payout ratio | C45: =IFERROR(C44/C41,0) -> 0.66180579 | D45: =IFERROR(D44/D41,0) -> 0.6792714 | E45: =IFERROR(E44/E41,0) -> 0.65536016 | F45: =IFERROR(F44/F41,0) -> 0.94695593 | G45: =IFERROR(G44/G41,0) -> 1.2245091 | H45: =IFERROR(H44/H41,0) -> 1.0425493 | I45: =IFERROR(I44/I41,0) -> 1.1084246 | J45: =IFERROR(J44/J41,0) -> 0.98539399 | ... M45: =IFERROR(M44/M41,0) -> 0
B47: Retained Earnings | C47: =IFERROR(IF(C41>C44,1-C45,0),0) -> 0.33819421 | D47: =IFERROR(IF(D41>D44,1-D45,0),0) -> 0.3207286 | E47: =IFERROR(IF(E41>E44,1-E45,0),0) -> 0.34463984 | F47: =IFERROR(IF(F41>F44,1-F45,0),0) -> 0.053044068 | G47: =IFERROR(IF(G41>G44,1-G45,0),0) -> 0 | H47: =IFERROR(IF(H41>H44,1-H45,0),0) -> 0 | I47: =IFERROR(IF(I41>I44,1-I45,0),0) -> 0 | J47: =IFERROR(IF(J41>J44,1-J45,0),0) -> 0.014606011 | ... M47: =IFERROR(IF(M41>M44,1-M45,0),0) -> 1
A49: # | B49: Balance Sheet
B50: Equity Share Capital | C50: =IFERROR('Data Sheet'!B57,0) -> 1214.74 | D50: =IFERROR('Data Sheet'!C57,0) -> 1220.43 | E50: =IFERROR('Data Sheet'!D57,0) -> 1225.86 | F50: =IFERROR('Data Sheet'!E57,0) -> 1229.22 | G50: =IFERROR('Data Sheet'!F57,0) -> 1230.88 | H50: =IFERROR('Data Sheet'!G57,0) -> 1232.33 | I50: =IFERROR('Data Sheet'!H57,0) -> 1242.8 | J50: =IFERROR('Data Sheet'!I57,0) -> 1248.47 | ... L50: =IFERROR('Data Sheet'!K57,0) -> 1252.95
B51: Reserves | C51: =IFERROR('Data Sheet'!B58,0) -> 45198.19 | D51: =IFERROR('Data Sheet'!C58,0) -> 51289.68 | E51: =IFERROR('Data Sheet'!D58,0) -> 57915.01 | F51: =IFERROR('Data Sheet'!E58,0) -> 64044.04 | G51: =IFERROR('Data Sheet'!F58,0) -> 59116.46 | H51: =IFERROR('Data Sheet'!G58,0) -> 61223.24 | I51: =IFERROR('Data Sheet'!H58,0) -> 67912.46 | J51: =IFERROR('Data Sheet'!I58,0) -> 73258.53 | ... L51: =IFERROR('Data Sheet'!K58,0) -> 71254.35
B52: Borrowings | C52: =IFERROR('Data Sheet'!B59,0) -> 45.72 | D52: =IFERROR('Data Sheet'!C59,0) -> 35.92 | E52: =IFERROR('Data Sheet'!D59,0) -> 13.44 | F52: =IFERROR('Data Sheet'!E59,0) -> 277.45 | G52: =IFERROR('Data Sheet'!F59,0) -> 270.83 | H52: =IFERROR('Data Sheet'!G59,0) -> 249.44 | I52: =IFERROR('Data Sheet'!H59,0) -> 306.04 | J52: =IFERROR('Data Sheet'!I59,0) -> 303.43 | ... L52: =IFERROR('Data Sheet'!K59,0) -> 2399.06
B53: Other Liabilities | C53: =IFERROR('Data Sheet'!B60,0) -> 9439.67 | D53: =IFERROR('Data Sheet'!C60,0) -> 11694.85 | E53: =IFERROR('Data Sheet'!D60,0) -> 12584.73 | F53: =IFERROR('Data Sheet'!E60,0) -> 11760.04 | G53: =IFERROR('Data Sheet'!F60,0) -> 13142.59 | H53: =IFERROR('Data Sheet'!G60,0) -> 14491.01 | I53: =IFERROR('Data Sheet'!H60,0) -> 16369.66 | J53: =IFERROR('Data Sheet'!I60,0) -> 16943.54 | ... L53: =IFERROR('Data Sheet'!K60,0) -> 18730.84
B54: Total Liabilities | C54: =IFERROR('Data Sheet'!B61,0) -> 55898.32 | D54: =IFERROR('Data Sheet'!C61,0) -> 64240.88 | E54: =IFERROR('Data Sheet'!D61,0) -> 71739.04 | F54: =IFERROR('Data Sheet'!E61,0) -> 77310.75 | G54: =IFERROR('Data Sheet'!F61,0) -> 73760.76 | H54: =IFERROR('Data Sheet'!G61,0) -> 77196.02 | I54: =IFERROR('Data Sheet'!H61,0) -> 85830.96 | J54: =IFERROR('Data Sheet'!I61,0) -> 91753.97 | ... L54: =IFERROR('Data Sheet'!K61,0) -> 93637.2
B56: Fixed Assets Net Block | C56: =IFERROR('Data Sheet'!B62,0) -> 15893.48 | D56: =IFERROR('Data Sheet'!C62,0) -> 16523.96 | E56: =IFERROR('Data Sheet'!D62,0) -> 19374.19 | F56: =IFERROR('Data Sheet'!E62,0) -> 21713.34 | G56: =IFERROR('Data Sheet'!F62,0) -> 23298.48 | H56: =IFERROR('Data Sheet'!G62,0) -> 24231.59 | I56: =IFERROR('Data Sheet'!H62,0) -> 25851.27 | J56: =IFERROR('Data Sheet'!I62,0) -> 27820.22 | ... L56: =IFERROR('Data Sheet'!K62,0) -> 22442.53
B57: Capital Work in Progress | C57: =IFERROR('Data Sheet'!B63,0) -> 3729.89 | D57: =IFERROR('Data Sheet'!C63,0) -> 5508.33 | E57: =IFERROR('Data Sheet'!D63,0) -> 4136.42 | F57: =IFERROR('Data Sheet'!E63,0) -> 3256.46 | G57: =IFERROR('Data Sheet'!F63,0) -> 4011.29 | H57: =IFERROR('Data Sheet'!G63,0) -> 3225.54 | I57: =IFERROR('Data Sheet'!H63,0) -> 3003.3 | J57: =IFERROR('Data Sheet'!I63,0) -> 2860.78 | ... L57: =IFERROR('Data Sheet'!K63,0) -> 1601.88
B58: Investments | C58: =IFERROR('Data Sheet'!B64,0) -> 17581.38 | D58: =IFERROR('Data Sheet'!C64,0) -> 22052.86 | E58: =IFERROR('Data Sheet'!D64,0) -> 25043.49 | F58: =IFERROR('Data Sheet'!E64,0) -> 28663.35 | G58: =IFERROR('Data Sheet'!F64,0) -> 24870.87 | H58: =IFERROR('Data Sheet'!G64,0) -> 24841.01 | I58: =IFERROR('Data Sheet'!H64,0) -> 29415.02 | J58: =IFERROR('Data Sheet'!I64,0) -> 31114.02 | ... L58: =IFERROR('Data Sheet'!K64,0) -> 38128.43
...

Sheet Common Size Statement
A2: # | B2: ="Common Size Income Statement - "&'Data Sheet'!$B$1 -> Common Size Income Statement - ITC LTD
B3: Particulars | C3: ='Data Sheet'!B16 -> 42825 | D3: ='Data Sheet'!C16 -> 43190 | E3: ='Data Sheet'!D16 -> 43555 | F3: ='Data Sheet'!E16 -> 43921 | G3: ='Data Sheet'!F16 -> 44286 | H3: ='Data Sheet'!G16 -> 44651 | I3: ='Data Sheet'!H16 -> 45016 | J3: ='Data Sheet'!I16 -> 45382 | ... L3: ='Data Sheet'!K16 -> 46112
B5: ='Data Sheet'!A17 -> Sales | C5: ='Data Sheet'!B17/'Data Sheet'!B$17 -> 1 | D5: ='Data Sheet'!C17/'Data Sheet'!C$17 -> 1 | E5: ='Data Sheet'!D17/'Data Sheet'!D$17 -> 1 | F5: ='Data Sheet'!E17/'Data Sheet'!E$17 -> 1 | G5: ='Data Sheet'!F17/'Data Sheet'!F$17 -> 1 | H5: ='Data Sheet'!G17/'Data Sheet'!G$17 -> 1 | I5: ='Data Sheet'!H17/'Data Sheet'!H$17 -> 1 | J5: ='Data Sheet'!I17/'Data Sheet'!I$17 -> 1 | ... L5: ='Data Sheet'!K17/'Data Sheet'!K$17 -> 1
B6: ='Data Sheet'!A18 -> Raw Material Cost | C6: ='Data Sheet'!B18/'Data Sheet'!B$17 -> 0.36140887 | D6: ='Data Sheet'!C18/'Data Sheet'!C$17 -> 0.3412677 | E6: ='Data Sheet'!D18/'Data Sheet'!D$17 -> 0.36457743 | F6: ='Data Sheet'!E18/'Data Sheet'!E$17 -> 0.36544727 | G6: ='Data Sheet'!F18/'Data Sheet'!F$17 -> 0.42179833 | H6: ='Data Sheet'!G18/'Data Sheet'!G$17 -> 0.44638924 | I6: ='Data Sheet'!H18/'Data Sheet'!H$17 -> 0.41405473 | J6: ='Data Sheet'!I18/'Data Sheet'!I$17 -> 0.4025878 | ... L6: ='Data Sheet'!K18/'Data Sheet'!K$17 -> 0.44502412
B7: ='Data Sheet'!A19 -> Change in Inventory | C7: ='Data Sheet'!B19/'Data Sheet'!B$17 -> -0.013855582 | D7: ='Data Sheet'!C19/'Data Sheet'!C$17 -> -0.023654432 | E7: ='Data Sheet'!D19/'Data Sheet'!D$17 -> 0.0042033878 | F7: ='Data Sheet'!E19/'Data Sheet'!E$17 -> 0.014236946 | G7: ='Data Sheet'!F19/'Data Sheet'!F$17 -> 0.013099947 | H7: ='Data Sheet'!G19/'Data Sheet'!G$17 -> 0.011311818 | I7: ='Data Sheet'!H19/'Data Sheet'!H$17 -> 0.0050563297 | J7: ='Data Sheet'!I19/'Data Sheet'!I$17 -> 0.0054138009 | ... L7: ='Data Sheet'!K19/'Data Sheet'!K$17 -> 0.032338173
B8: ='Data Sheet'!A20 -> Power and Fuel | C8: ='Data Sheet'!B20/'Data Sheet'!B$17 -> 0.013662913 | D8: ='Data Sheet'!C20/'Data Sheet'!C$17 -> 0.015040643 | E8: ='Data Sheet'!D20/'Data Sheet'!D$17 -> 0.01544759 | F8: ='Data Sheet'!E20/'Data Sheet'!E$17 -> 0.015810617 | G8: ='Data Sheet'!F20/'Data Sheet'!F$17 -> 0.014202116 | H8: ='Data Sheet'!G20/'Data Sheet'!G$17 -> 0.01467189 | I8: ='Data Sheet'!H20/'Data Sheet'!H$17 -> 0.017376718 | J8: ='Data Sheet'!I20/'Data Sheet'!I$17 -> 0.014027275 | ... L8: ='Data Sheet'!K20/'Data Sheet'!K$17 -> 0.012016346
B9: ='Data Sheet'!A21 -> Other Mfr. Exp | C9: ='Data Sheet'!B21/'Data Sheet'!B$17 -> 0.039373264 | D9: ='Data Sheet'!C21/'Data Sheet'!C$17 -> 0.039071609 | E9: ='Data Sheet'!D21/'Data Sheet'!D$17 -> 0.038705549 | F9: ='Data Sheet'!E21/'Data Sheet'!E$17 -> 0.038638973 | G9: ='Data Sheet'!F21/'Data Sheet'!F$17 -> 0.032222131 | H9: ='Data Sheet'!G21/'Data Sheet'!G$17 -> 0.031126792 | I9: ='Data Sheet'!H21/'Data Sheet'!H$17 -> 0.032823348 | J9: ='Data Sheet'!I21/'Data Sheet'!I$17 -> 0.032146292 | ... L9: ='Data Sheet'!K21/'Data Sheet'!K$17 -> 0.032744166
B10: ='Data Sheet'!A22 -> Employee Cost | C10: ='Data Sheet'!B22/'Data Sheet'!B$17 -> 0.084917788 | D10: ='Data Sheet'!C22/'Data Sheet'!C$17 -> 0.086559074 | E10: ='Data Sheet'!D22/'Data Sheet'!D$17 -> 0.086427727 | F10: ='Data Sheet'!E22/'Data Sheet'!E$17 -> 0.086980969 | G10: ='Data Sheet'!F22/'Data Sheet'!F$17 -> 0.090612283 | H10: ='Data Sheet'!G22/'Data Sheet'!G$17 -> 0.080642874 | I10: ='Data Sheet'!H22/'Data Sheet'!H$17 -> 0.080884073 | J10: ='Data Sheet'!I22/'Data Sheet'!I$17 -> 0.081677779 | ... L10: ='Data Sheet'!K22/'Data Sheet'!K$17 -> 0.085985008
B11: ='Data Sheet'!A23 -> Selling and admin | C11: ='Data Sheet'!B23/'Data Sheet'!B$17 -> 0.09773146 | D11: ='Data Sheet'!C23/'Data Sheet'!C$17 -> 0.091023394 | E11: ='Data Sheet'!D23/'Data Sheet'!D$17 -> 0.094051086 | F11: ='Data Sheet'!E23/'Data Sheet'!E$17 -> 0.090885585 | G11: ='Data Sheet'!F23/'Data Sheet'!F$17 -> 0.086012776 | H11: ='Data Sheet'!G23/'Data Sheet'!G$17 -> 0.080112406 | I11: ='Data Sheet'!H23/'Data Sheet'!H$17 -> 0.079020821 | J11: ='Data Sheet'!I23/'Data Sheet'!I$17 -> 0.078202536 | ... L11: ='Data Sheet'!K23/'Data Sheet'!K$17 -> 0.080868256
B12: ='Data Sheet'!A24 -> Other Expenses | C12: ='Data Sheet'!B24/'Data Sheet'!B$17 -> 0.027339154 | D12: ='Data Sheet'!C24/'Data Sheet'!C$17 -> 0.023153154 | E12: ='Data Sheet'!D24/'Data Sheet'!D$17 -> 0.021511358 | F12: ='Data Sheet'!E24/'Data Sheet'!E$17 -> 0.024806379 | G12: ='Data Sheet'!F24/'Data Sheet'!F$17 -> 0.021811726 | H12: ='Data Sheet'!G24/'Data Sheet'!G$17 -> 0.018302555 | I12: ='Data Sheet'!H24/'Data Sheet'!H$17 -> 0.018451465 | J12: ='Data Sheet'!I24/'Data Sheet'!I$17 -> 0.025996166 | ... L12: ='Data Sheet'!K24/'Data Sheet'!K$17 -> 0.029477966
B13: ='Data Sheet'!A25 -> Other Income | C13: ='Data Sheet'!B25/'Data Sheet'!B$17 -> 0.041120615 | D13: ='Data Sheet'!C25/'Data Sheet'!C$17 -> 0.051550395 | E13: ='Data Sheet'!D25/'Data Sheet'!D$17 -> 0.043038024 | F13: ='Data Sheet'!E25/'Data Sheet'!E$17 -> 0.04894579 | G13: ='Data Sheet'!F25/'Data Sheet'!F$17 -> 0.052315944 | H13: ='Data Sheet'!G25/'Data Sheet'!G$17 -> 0.031490386 | I13: ='Data Sheet'!H25/'Data Sheet'!H$17 -> 0.029577957 | J13: ='Data Sheet'!I25/'Data Sheet'!I$17 -> 0.049026275 | ... L13: ='Data Sheet'!K25/'Data Sheet'!K$17 -> 0.03199114
B14: ='Data Sheet'!A26 -> Depreciation | C14: ='Data Sheet'!B26/'Data Sheet'!B$17 -> 0.026954751 | D14: ='Data Sheet'!C26/'Data Sheet'!C$17 -> 0.028453629 | E14: ='Data Sheet'!D26/'Data Sheet'!D$17 -> 0.028891645 | F14: ='Data Sheet'!E26/'Data Sheet'!E$17 -> 0.033306066 | G14: ='Data Sheet'!F26/'Data Sheet'!F$17 -> 0.033407941 | H14: ='Data Sheet'!G26/'Data Sheet'!G$17 -> 0.028566628 | I14: ='Data Sheet'!H26/'Data Sheet'!H$17 -> 0.025508104 | J14: ='Data Sheet'!I26/'Data Sheet'!I$17 -> 0.022346631 | ... L14: ='Data Sheet'!K26/'Data Sheet'!K$17 -> 0.021688408
B15: ='Data Sheet'!A27 -> Interest | C15: ='Data Sheet'!B27/'Data Sheet'!B$17 -> 0.0011464286 | D15: ='Data Sheet'!C27/'Data Sheet'!C$17 -> 0.0026470151 | E15: ='Data Sheet'!D27/'Data Sheet'!D$17 -> 0.0014770505 | F15: ='Data Sheet'!E27/'Data Sheet'!E$17 -> 0.0016477787 | G15: ='Data Sheet'!F27/'Data Sheet'!F$17 -> 0.0011768778 | H15: ='Data Sheet'!G27/'Data Sheet'!G$17 -> 0.00098920694 | I15: ='Data Sheet'!H27/'Data Sheet'!H$17 -> 0.0010966027 | J15: ='Data Sheet'!I27/'Data Sheet'!I$17 -> 0.00057572329 | ... L15: ='Data Sheet'!K27/'Data Sheet'!K$17 -> 0.0010799002
B16: ='Data Sheet'!A28 -> Profit before tax | C16: ='Data Sheet'!B28/'Data Sheet'!B$17 -> 0.3747304 | D16: ='Data Sheet'!C28/'Data Sheet'!C$17 -> 0.40067974 | E16: ='Data Sheet'!D28/'Data Sheet'!D$17 -> 0.39615197 | F16: ='Data Sheet'!E28/'Data Sheet'!E$17 -> 0.4056591 | G16: ='Data Sheet'!F28/'Data Sheet'!F$17 -> 0.36417171 | H16: ='Data Sheet'!G28/'Data Sheet'!G$17 -> 0.34200062 | I16: ='Data Sheet'!H28/'Data Sheet'!H$17 -> 0.36541842 | J16: ='Data Sheet'!I28/'Data Sheet'!I$17 -> 0.39687988 | ... L16: ='Data Sheet'!K28/'Data Sheet'!K$17 -> 0.35544515
... B19: ='Data Sheet'!A31 -> Dividend Amount | C19: ='Data Sheet'!B31/'Data Sheet'!B$17 -> 0.13491568 | D19: ='Data Sheet'!C31/'Data Sheet'!C$17 -> 0.14465738 | E19: ='Data Sheet'!D31/'Data Sheet'!D$17 -> 0.14581633 | F19: ='Data Sheet'!E31/'Data Sheet'!E$17 -> 0.25262525 | G19: ='Data Sheet'!F31/'Data Sheet'!F$17 -> 0.2686286 | H19: ='Data Sheet'!G31/'Data Sheet'!G$17 -> 0.23368633 | I19: ='Data Sheet'!H31/'Data Sheet'!H$17 -> 0.27162526 | J19: ='Data Sheet'!I31/'Data Sheet'!I$17 -> 0.25270087 | ... L19: ='Data Sheet'!K31/'Data Sheet'!K$17 -> 0.23035563
B20: ='Data Sheet'!A34 -> EBITDA | C20: ='Data Sheet'!B34/'Data Sheet'!B$17 -> 0.39844064 | D20: ='Data Sheet'!C34/'Data Sheet'!C$17 -> 0.42668291 | E20: ='Data Sheet'!D34/'Data Sheet'!D$17 -> 0.42148194 | F20: ='Data Sheet'!E34/'Data Sheet'!E$17 -> 0.43481089 | G20: ='Data Sheet'!F34/'Data Sheet'!F$17 -> 0.39425589 | H20: ='Data Sheet'!G34/'Data Sheet'!G$17 -> 0.36726142 | I20: ='Data Sheet'!H34/'Data Sheet'!H$17 -> 0.38800361 | J20: ='Data Sheet'!I34/'Data Sheet'!I$17 -> 0.41549527 | ... L20: ='Data Sheet'!K34/'Data Sheet'!K$17 -> 0.37404601
A22: # | B22: ="Common Size Balance Sheet - "&'Data Sheet'!$B$1 -> Common Size Balance Sheet - ITC LTD
B23: Particulars | C23: ='Data Sheet'!B56 -> 42825 | D23: ='Data Sheet'!C56 -> 43190 | E23: ='Data Sheet'!D56 -> 43555 | F23: ='Data Sheet'!E56 -> 43921 | G23: ='Data Sheet'!F56 -> 44286 | H23: ='Data Sheet'!G56 -> 44651 | I23: ='Data Sheet'!H56 -> 45016 | J23: ='Data Sheet'!I56 -> 45382 | ... L23: ='Data Sheet'!K56 -> 46112
B25: Total Liabilities | C25: ='Data Sheet'!B61/'Data Sheet'!B$61 -> 1 | D25: ='Data Sheet'!C61/'Data Sheet'!C$61 -> 1 | E25: ='Data Sheet'!D61/'Data Sheet'!D$61 -> 1 | F25: ='Data Sheet'!E61/'Data Sheet'!E$61 -> 1 | G25: ='Data Sheet'!F61/'Data Sheet'!F$61 -> 1 | H25: ='Data Sheet'!G61/'Data Sheet'!G$61 -> 1 | I25: ='Data Sheet'!H61/'Data Sheet'!H$61 -> 1 | J25: ='Data Sheet'!I61/'Data Sheet'!I$61 -> 1 | ... L25: ='Data Sheet'!K61/'Data Sheet'!K$61 -> 1
B26: ='Data Sheet'!A57 -> Equity Share Capital | C26: ='Data Sheet'!B57/'Data Sheet'!B$61 -> 0.021731243 | D26: ='Data Sheet'!C57/'Data Sheet'!C$61 -> 0.018997716 | E26: ='Data Sheet'!D57/'Data Sheet'!D$61 -> 0.017087767 | F26: ='Data Sheet'!E57/'Data Sheet'!E$61 -> 0.015899729 | G26: ='Data Sheet'!F57/'Data Sheet'!F$61 -> 0.016687464 | H26: ='Data Sheet'!G57/'Data Sheet'!G$61 -> 0.015963647 | I26: ='Data Sheet'!H57/'Data Sheet'!H$61 -> 0.014479624 | J26: ='Data Sheet'!I57/'Data Sheet'!I$61 -> 0.013606714 | ... L26: ='Data Sheet'!K57/'Data Sheet'!K$61 -> 0.0133809
B27: ='Data Sheet'!A58 -> Reserves | C27: ='Data Sheet'!B58/'Data Sheet'!B$61 -> 0.80857868 | D27: ='Data Sheet'!C58/'Data Sheet'!C$61 -> 0.79839629 | E27: ='Data Sheet'!D58/'Data Sheet'!D$61 -> 0.80730116 | F27: ='Data Sheet'!E58/'Data Sheet'!E$61 -> 0.8283976 | G27: ='Data Sheet'!F58/'Data Sheet'!F$61 -> 0.80146219 | H27: ='Data Sheet'!G58/'Data Sheet'!G$61 -> 0.79308804 | I27: ='Data Sheet'!H58/'Data Sheet'!H$61 -> 0.791235 | J27: ='Data Sheet'!I58/'Data Sheet'!I$61 -> 0.79842355 | ... L27: ='Data Sheet'!K58/'Data Sheet'!K$61 -> 0.76096199
B28: ='Data Sheet'!A59 -> Borrowings | C28: ='Data Sheet'!B59/'Data Sheet'!B$61 -> 0.00081791367 | D28: ='Data Sheet'!C59/'Data Sheet'!C$61 -> 0.00055914552 | E28: ='Data Sheet'!D59/'Data Sheet'!D$61 -> 0.00018734569 | F28: ='Data Sheet'!E59/'Data Sheet'!E$61 -> 0.0035887635 | G28: ='Data Sheet'!F59/'Data Sheet'!F$61 -> 0.0036717355 | H28: ='Data Sheet'!G59/'Data Sheet'!G$61 -> 0.0032312547 | I28: ='Data Sheet'!H59/'Data Sheet'!H$61 -> 0.0035656132 | J28: ='Data Sheet'!I59/'Data Sheet'!I$61 -> 0.0033069959 | ... L28: ='Data Sheet'!K59/'Data Sheet'!K$61 -> 0.0256208
B29: ='Data Sheet'!A60 -> Other Liabilities | C29: ='Data Sheet'!B60/'Data Sheet'!B$61 -> 0.16887216 | D29: ='Data Sheet'!C60/'Data Sheet'!C$61 -> 0.18204685 | E29: ='Data Sheet'!D60/'Data Sheet'!D$61 -> 0.17542373 | F29: ='Data Sheet'!E60/'Data Sheet'!E$61 -> 0.1521139 | G29: ='Data Sheet'!F60/'Data Sheet'!F$61 -> 0.17817861 | H29: ='Data Sheet'!G60/'Data Sheet'!G$61 -> 0.18771706 | I29: ='Data Sheet'!H60/'Data Sheet'!H$61 -> 0.19071976 | J29: ='Data Sheet'!I60/'Data Sheet'!I$61 -> 0.18466275 | ... L29: ='Data Sheet'!K60/'Data Sheet'!K$61 -> 0.20003631
B31: Total Assets | C31: ='Data Sheet'!B76/'Data Sheet'!B$76 -> 1 | D31: ='Data Sheet'!C76/'Data Sheet'!C$76 -> 1 | E31: ='Data Sheet'!D76/'Data Sheet'!D$76 -> 1 | F31: ='Data Sheet'!E76/'Data Sheet'!E$76 -> 1 | G31: ='Data Sheet'!F76/'Data Sheet'!F$76 -> 1 | H31: ='Data Sheet'!G76/'Data Sheet'!G$76 -> 1 | I31: ='Data Sheet'!H76/'Data Sheet'!H$76 -> 1 | J31: ='Data Sheet'!I76/'Data Sheet'!I$76 -> 1 | ... L31: ='Data Sheet'!K76/'Data Sheet'!K$76 -> 1
B32: ='Data Sheet'!A62 -> Net Block | C32: ='Data Sheet'!B62/'Data Sheet'!B$76 -> 0.2843284 | D32: ='Data Sheet'!C62/'Data Sheet'!C$76 -> 0.25721877 | E32: ='Data Sheet'!D62/'Data Sheet'!D$76 -> 0.27006481 | F32: ='Data Sheet'!E62/'Data Sheet'!E$76 -> 0.28085797 | G32: ='Data Sheet'!F62/'Data Sheet'!F$76 -> 0.31586551 | H32: ='Data Sheet'!G62/'Data Sheet'!G$76 -> 0.31389688 | I32: ='Data Sheet'!H62/'Data Sheet'!H$76 -> 0.30118817 | J32: ='Data Sheet'!I62/'Data Sheet'!I$76 -> 0.30320454 | ... L32: ='Data Sheet'!K62/'Data Sheet'!K$76 -> 0.23967536
B33: ='Data Sheet'!A63 -> Capital Work in Progress | C33: ='Data Sheet'!B63/'Data Sheet'!B$76 -> 0.066726335 | D33: ='Data Sheet'!C63/'Data Sheet'!C$76 -> 0.085744934 | E33: ='Data Sheet'!D63/'Data Sheet'!D$76 -> 0.057659261 | F33: ='Data Sheet'!E63/'Data Sheet'!E$76 -> 0.042121697 | G33: ='Data Sheet'!F63/'Data Sheet'!F$76 -> 0.054382439 | H33: ='Data Sheet'!G63/'Data Sheet'!G$76 -> 0.04178376 | I33: ='Data Sheet'!H63/'Data Sheet'!H$76 -> 0.03499087 | J33: ='Data Sheet'!I63/'Data Sheet'!I$76 -> 0.031178814 | ... L33: ='Data Sheet'!K63/'Data Sheet'!K$76 -> 0.017107304
B34: ='Data Sheet'!A64 -> Investments | C34: ='Data Sheet'!B64/'Data Sheet'!B$76 -> 0.3145243 | D34: ='Data Sheet'!C64/'Data Sheet'!C$76 -> 0.3432839 | E34: ='Data Sheet'!D64/'Data Sheet'!D$76 -> 0.34909151 | F34: ='Data Sheet'!E64/'Data Sheet'!E$76 -> 0.37075504 | G34: ='Data Sheet'!F64/'Data Sheet'!F$76 -> 0.33718294 | H34: ='Data Sheet'!G64/'Data Sheet'!G$76 -> 0.32179133 | I34: ='Data Sheet'!H64/'Data Sheet'!H$76 -> 0.34270874 | J34: ='Data Sheet'!I64/'Data Sheet'!I$76 -> 0.33910271 | ... L34: ='Data Sheet'!K64/'Data Sheet'!K$76 -> 0.40719319
B35: ='Data Sheet'!A65 -> Other Assets | C35: ='Data Sheet'!B65/'Data Sheet'!B$76 -> 0.33442096 | D35: ='Data Sheet'!C65/'Data Sheet'!C$76 -> 0.3137524 | E35: ='Data Sheet'!D65/'Data Sheet'!D$76 -> 0.32318442 | F35: ='Data Sheet'!E65/'Data Sheet'!E$76 -> 0.3062653 | G35: ='Data Sheet'!F65/'Data Sheet'!F$76 -> 0.29256911 | H35: ='Data Sheet'!G65/'Data Sheet'!G$76 -> 0.32252803 | I35: ='Data Sheet'!H65/'Data Sheet'!H$76 -> 0.32111222 | J35: ='Data Sheet'!I65/'Data Sheet'!I$76 -> 0.32651394 | ... L35: ='Data Sheet'!K65/'Data Sheet'!K$76 -> 0.33602414
B36: ='Data Sheet'!A67 -> Receivables | C36: ='Data Sheet'!B67/'Data Sheet'!B$76 -> 0.044264121 | D36: ='Data Sheet'!C67/'Data Sheet'!C$76 -> 0.041753631 | E36: ='Data Sheet'!D67/'Data Sheet'!D$76 -> 0.056249428 | F36: ='Data Sheet'!E67/'Data Sheet'!E$76 -> 0.033145196 | G36: ='Data Sheet'!F67/'Data Sheet'!F$76 -> 0.033916408 | H36: ='Data Sheet'!G67/'Data Sheet'!G$76 -> 0.031891541 | I36: ='Data Sheet'!H67/'Data Sheet'!H$76 -> 0.034441768 | J36: ='Data Sheet'!I67/'Data Sheet'!I$76 -> 0.043876249 | ... L36: ='Data Sheet'!K67/'Data Sheet'!K$76 -> 0.041894247
B37: ='Data Sheet'!A68 -> Inventory | C37: ='Data Sheet'!B68/'Data Sheet'!B$76 -> 0.14519399 | D37: ='Data Sheet'!C68/'Data Sheet'!C$76 -> 0.11667166 | E37: ='Data Sheet'!D68/'Data Sheet'!D$76 -> 0.10955764 | F37: ='Data Sheet'!E68/'Data Sheet'!E$76 -> 0.11485246 | G37: ='Data Sheet'!F68/'Data Sheet'!F$76 -> 0.14095788 | H37: ='Data Sheet'!G68/'Data Sheet'!G$76 -> 0.14073459 | I37: ='Data Sheet'!H68/'Data Sheet'!H$76 -> 0.13714352 | J37: ='Data Sheet'!I68/'Data Sheet'!I$76 -> 0.15424815 | ... L37: ='Data Sheet'!K68/'Data Sheet'!K$76 -> 0.1988842
B38: ='Data Sheet'!A69 -> Cash & Bank | C38: ='Data Sheet'!B69/'Data Sheet'!B$76 -> 0.053085674 | D38: ='Data Sheet'!C69/'Data Sheet'!C$76 -> 0.045136368 | E38: ='Data Sheet'!D69/'Data Sheet'!D$76 -> 0.057876855 | F38: ='Data Sheet'!E69/'Data Sheet'!E$76 -> 0.094131023 | G38: ='Data Sheet'!F69/'Data Sheet'!F$76 -> 0.063163937 | H38: ='Data Sheet'!G69/'Data Sheet'!G$76 -> 0.060293523 | I38: ='Data Sheet'!H69/'Data Sheet'!H$76 -> 0.056858155 | J38: ='Data Sheet'!I69/'Data Sheet'!I$76 -> 0.078663408 | ... L38: ='Data Sheet'!K69/'Data Sheet'!K$76 -> 0.032132422

Sheet Ratio Analysis
B2: ="Ratio Analysis of - "&'Data Sheet'!B1 -> Ratio Analysis of - ITC LTD
B3: Years | C3: ='Data Sheet'!B16 -> 42825 | D3: ='Data Sheet'!C16 -> 43190 | E3: ='Data Sheet'!D16 -> 43555 | F3: ='Data Sheet'!E16 -> 43921 | G3: ='Data Sheet'!F16 -> 44286 | H3: ='Data Sheet'!G16 -> 44651 | I3: ='Data Sheet'!H16 -> 45016 | J3: ='Data Sheet'!I16 -> 45382 | ... L3: ='Data Sheet'!K16 -> 46112 | M3: Trend | N3: Mean | O3: Median
B5: SalesGrowth | D5: =IFERROR('Historical FS'!D7,0) -> 0.015931219 | E5: =IFERROR('Historical FS'!E7,0) -> 0.11256063 | F5: =IFERROR('Historical FS'!F7,0) -> 0.021682439 | G5: =IFERROR('Historical FS'!G7,0) -> -0.0026372963 | H5: =IFERROR('Historical FS'!H7,0) -> 0.23117498 | I5: =IFERROR('Historical FS'!I7,0) -> 0.16942152 | J5: =IFERROR('Historical FS'!J7,0) -> -0.042119724 | K5: =IFERROR('Historical FS'!K7,0) -> 0.10880596 | L5: =IFERROR('Historical FS'!L7,0) -> 0.047064562 | N5: =IFERROR(AVERAGE(D5:L5),0) -> 0.073542698 | O5: =IFERROR(MEDIAN(C5:M5),0) -> 0.047064562
B6: EBITDA Growth | D6: =IFERROR('Historical FS'!D18/'Historical FS'!C18-1,0) -> 0.067945268 | E6: =IFERROR('Historical FS'!E18/'Historical FS'!D18-1,0) -> 0.12207796 | F6: =IFERROR('Historical FS'!F18/'Historical FS'!E18-1,0) -> 0.043487783 | G6: =IFERROR('Historical FS'!G18/'Historical FS'!F18-1,0) -> -0.1178047 | H6: =IFERROR('Historical FS'!H18/'Historical FS'!G18-1,0) -> 0.20852129 | I6: =IFERROR('Historical FS'!I18/'Historical FS'!H18-1,0) -> 0.24637895 | J6: =IFERROR('Historical FS'!J18/'Historical FS'!I18-1,0) -> -0.020102893 | K6: =IFERROR('Historical FS'!K18/'Historical FS'!J18-1,0) -> 0.025570193 | L6: =IFERROR('Historical FS'!L18/'Historical FS'!K18-1,0) -> 0.057078197 | N6: =IFERROR(AVERAGE(D6:L6),0) -> 0.070350228 | O6: =IFERROR(MEDIAN(C6:M6),0) -> 0.057078197
B7: EBIT Growth | D7: =IFERROR('Historical FS'!D27/'Historical FS'!C27-1,0) -> 0.067584614 | E7: =IFERROR('Historical FS'!E27/'Historical FS'!D27-1,0) -> 0.12146247 | F7: =IFERROR('Historical FS'!F27/'Historical FS'!E27-1,0) -> 0.032545193 | G7: =IFERROR('Historical FS'!G27/'Historical FS'!F27-1,0) -> -0.12879189 | H7: =IFERROR('Historical FS'!H27/'Historical FS'!G27-1,0) -> 0.22514477 | I7: =IFERROR('Historical FS'!I27/'Historical FS'!H27-1,0) -> 0.26491869 | J7: =IFERROR('Historical FS'!J27/'Historical FS'!I27-1,0) -> -0.0094483213 | K7: =IFERROR('Historical FS'!K27/'Historical FS'!J27-1,0) -> 0.021790931 | L7: =IFERROR('Historical FS'!L27/'Historical FS'!K27-1,0) -> 0.058308656 | N7: =IFERROR(AVERAGE(D7:L7),0) -> 0.07261279 | O7: =IFERROR(MEDIAN(C7:M7),0) -> 0.058308656
B8: Net Profit Growth | D8: =IFERROR('Historical FS'!D36/'Historical FS'!C36-1,0) -> 0.061279334 | E8: =IFERROR('Historical FS'!E36/'Historical FS'!D36-1,0) -> 0.16239178 | F8: =IFERROR('Historical FS'!F36/'Historical FS'!E36-1,0) -> 0.225002 | G8: =IFERROR('Historical FS'!G36/'Historical FS'!F36-1,0) -> -0.1798442 | H8: =IFERROR('Historical FS'!H36/'Historical FS'!G36-1,0) -> 0.25795836 | I8: =IFERROR('Historical FS'!I36/'Historical FS'!H36-1,0) -> 0.27849303 | J8: =IFERROR('Historical FS'!J36/'Historical FS'!I36-1,0) -> 0.0024069168 | K8: =IFERROR('Historical FS'!K36/'Historical FS'!J36-1,0) -> -0.0098261227 | L8: =IFERROR('Historical FS'!L36/'Historical FS'!K36-1,0) -> 0.072194173 | N8: =IFERROR(AVERAGE(D8:L8),0) -> 0.096672809 | O8: =IFERROR(MEDIAN(C8:M8),0) -> 0.072194173
B9: Dividend Growth | D9: =IFERROR('Historical FS'!D44/'Historical FS'!C44-1,0) -> 0.084208811 | E9: =IFERROR('Historical FS'!E44/'Historical FS'!D44-1,0) -> 0.11650645 | F9: =IFERROR('Historical FS'!F44/'Historical FS'!E44-1,0) -> 0.76521571 | G9: =IFERROR('Historical FS'!G44/'Historical FS'!F44-1,0) -> 0.059113555 | H9: =IFERROR('Historical FS'!H44/'Historical FS'!G44-1,0) -> 0.069767819 | I9: =IFERROR('Historical FS'!I44/'Historical FS'!H44-1,0) -> 0.34782561 | J9: =IFERROR('Historical FS'!J44/'Historical FS'!I44-1,0) -> -0.11290335 | K9: =IFERROR('Historical FS'!K44/'Historical FS'!J44-1,0) -> 0.043636312 | L9: =IFERROR('Historical FS'!L44/'Historical FS'!K44-1,0) -> 0.010453437 | N9: =IFERROR(AVERAGE(D9:L9),0) -> 0.15375826 | O9: =IFERROR(MEDIAN(C9:M9),0) -> 0.069767819
B11: Gross Margin | C11: =IFERROR('Historical FS'!C13,0) -> 0.48678158 | D11: =IFERROR('Historical FS'!D13,0) -> 0.49440654 | E11: =IFERROR('Historical FS'!E13,0) -> 0.49904509 | F11: =IFERROR('Historical FS'!F13,0) -> 0.50735912 | G11: =IFERROR('Historical FS'!G13,0) -> 0.45426509 | H11: =IFERROR('Historical FS'!H13,0) -> 0.43848102 | I11: =IFERROR('Historical FS'!I13,0) -> 0.45991746 | J11: =IFERROR('Historical FS'!J13,0) -> 0.47497466 | ... L11: =IFERROR('Historical FS'!L13,0) -> 0.45656854 | N11: =IFERROR(AVERAGE(C11:L11),0) -> 0.47212498 | O11: =IFERROR(MEDIAN(C11:M11),0) -> 0.46744606
B12: EBITDA Margin | C12: =IFERROR('Historical FS'!C19,0) -> 0.36171097 | D12: =IFERROR('Historical FS'!D19,0) -> 0.38022999 | E12: =IFERROR('Historical FS'!E19,0) -> 0.38348265 | F12: =IFERROR('Historical FS'!F19,0) -> 0.39166716 | G12: =IFERROR('Historical FS'!G19,0) -> 0.34644059 | H12: =IFERROR('Historical FS'!H19,0) -> 0.34006606 | I12: =IFERROR('Historical FS'!I19,0) -> 0.36244517 | J12: =IFERROR('Historical FS'!J19,0) -> 0.37077596 | ... L12: =IFERROR('Historical FS'!L19,0) -> 0.34622231 | N12: =IFERROR(AVERAGE(C12:L12),0) -> 0.36259834 | O12: =IFERROR(MEDIAN(C12:M12),0) -> 0.36207807
B13: EBIT Margin | C13: =IFERROR('Historical FS'!C28,0) -> 0.33475622 | D13: =IFERROR('Historical FS'!D28,0) -> 0.35177636 | E13: =IFERROR('Historical FS'!E28,0) -> 0.354591 | F13: =IFERROR('Historical FS'!F28,0) -> 0.35836109 | G13: =IFERROR('Historical FS'!G28,0) -> 0.31303265 | H13: =IFERROR('Historical FS'!H28,0) -> 0.31149944 | I13: =IFERROR('Historical FS'!I28,0) -> 0.33693707 | J13: =IFERROR('Historical FS'!J28,0) -> 0.34842932 | ... L13: =IFERROR('Historical FS'!L28,0) -> 0.32453391 | N13: =IFERROR(AVERAGE(C13:L13),0) -> 0.33550029 | O13: =IFERROR(MEDIAN(C13:M13),0) -> 0.33584664
B14: EBT Margin | C14: =IFERROR('Historical FS'!C31,0) -> 0.33360979 | D14: =IFERROR('Historical FS'!D31,0) -> 0.34912935 | E14: =IFERROR('Historical FS'!E31,0) -> 0.35311395 | F14: =IFERROR('Historical FS'!F31,0) -> 0.35671331 | G14: =IFERROR('Historical FS'!G31,0) -> 0.31185577 | H14: =IFERROR('Historical FS'!H31,0) -> 0.31051023 | I14: =IFERROR('Historical FS'!I31,0) -> 0.33584046 | J14: =IFERROR('Historical FS'!J31,0) -> 0.3478536 | ... L14: =IFERROR('Historical FS'!L31,0) -> 0.32345401 | N14: =IFERROR(AVERAGE(C14:L14),0) -> 0.33425681 | O14: =IFERROR(MEDIAN(C14:M14),0) -> 0.33472513
B15: Net Profit Margin | C15: =IFERROR('Historical FS'!C37,0) -> 0.20385993 | D15: =IFERROR('Historical FS'!D37,0) -> 0.21295963 | E15: =IFERROR('Historical FS'!E37,0) -> 0.222498 | F15: =IFERROR('Historical FS'!F37,0) -> 0.26677614 | G15: =IFERROR('Historical FS'!G37,0) -> 0.21937656 | H15: =IFERROR('Historical FS'!H37,0) -> 0.22414895 | I15: =IFERROR('Historical FS'!I37,0) -> 0.24505524 | J15: =IFERROR('Historical FS'!J37,0) -> 0.25644653 | ... L15: =IFERROR('Historical FS'!L37,0) -> 0.23450533 | N15: =IFERROR(AVERAGE(C15:L15),0) -> 0.23146354 | O15: =IFERROR(MEDIAN(C15:M15),0) -> 0.22657902
B17: SalesExpenses%Sales | C17: =IFERROR('Historical FS'!C16,0) -> 0.12507061 | D17: =IFERROR('Historical FS'!D16,0) -> 0.11417655 | E17: =IFERROR('Historical FS'!E16,0) -> 0.11556244 | F17: =IFERROR('Historical FS'!F16,0) -> 0.11569196 | G17: =IFERROR('Historical FS'!G16,0) -> 0.1078245 | H17: =IFERROR('Historical FS'!H16,0) -> 0.09841496 | I17: =IFERROR('Historical FS'!I16,0) -> 0.097472286 | J17: =IFERROR('Historical FS'!J16,0) -> 0.1041987 | ... L17: =IFERROR('Historical FS'!L16,0) -> 0.11034622 | N17: =IFERROR(AVERAGE(C17:L17),0) -> 0.10952664 | O17: =IFERROR(MEDIAN(C17:M17),0) -> 0.10908536
B18: Depreciation%Sales | C18: =IFERROR('Historical FS'!C25,0) -> 0.026954751 | D18: =IFERROR('Historical FS'!D25,0) -> 0.028453629 | E18: =IFERROR('Historical FS'!E25,0) -> 0.028891645 | F18: =IFERROR('Historical FS'!F25,0) -> 0.033306066 | G18: =IFERROR('Historical FS'!G25,0) -> 0.033407941 | H18: =IFERROR('Historical FS'!H25,0) -> 0.028566628 | I18: =IFERROR('Historical FS'!I25,0) -> 0.025508104 | J18: =IFERROR('Historical FS'!J25,0) -> 0.022346631 | ... L18: =IFERROR('Historical FS'!L25,0) -> 0.021688408 | N18: =IFERROR(AVERAGE(C18:L18),0) -> 0.027098051 | O18: =IFERROR(MEDIAN(C18:M18),0) -> 0.02770419
B19: OperatingIncome%Sales | C19: =C15 -> 0.20385993 | D19: =D15 -> 0.21295963 | E19: =E15 -> 0.222498 | F19: =F15 -> 0.26677614 | G19: =G15 -> 0.21937656 | H19: =H15 -> 0.22414895 | I19: =I15 -> 0.24505524 | J19: =J15 -> 0.25644653 | ... L19: =L15 -> 0.23450533 | N19: =IFERROR(AVERAGE(C19:L19),0) -> 0.23146354 | O19: =IFERROR(MEDIAN(C19:M19),0) -> 0.22657902
B21: Return on Capital Employed | C21: =IFERROR('Historical FS'!C27/(SUM('Historical FS'!C50:C52)),0) -> 0.30816048 | D21: =IFERROR('Historical FS'!D27/(SUM('Historical FS'!D50:D52)),0) -> 0.29087469 | E21: =IFERROR('Historical FS'!E27/(SUM('Historical FS'!E50:E52)),0) -> 0.28976384 | F21: =IFERROR('Historical FS'!F27/(SUM('Historical FS'!F50:F52)),0) -> 0.26999906 | G21: =IFERROR('Historical FS'!G27/(SUM('Historical FS'!G50:G52)),0) -> 0.25436581 | H21: =IFERROR('Historical FS'!H27/(SUM('Historical FS'!H50:H52)),0) -> 0.30126365 | I21: =IFERROR('Historical FS'!I27/(SUM('Historical FS'!I50:I52)),0) -> 0.3440081 | J21: =IFERROR('Historical FS'!J27/(SUM('Historical FS'!J50:J52)),0) -> 0.31639278 | ... L21: =IFERROR('Historical FS'!L27/(SUM('Historical FS'!L50:L52)),0) -> 0.34169956 | N21: =IFERROR(AVERAGE(C21:L21),0) -> 0.30604859 | O21: =IFERROR(MEDIAN(C21:M21),0) -> 0.30471206
B22: Retained Earnings% | C22: =IFERROR('Historical FS'!C47,0) -> 0.33819421 | D22: =IFERROR('Historical FS'!D47,0) -> 0.3207286 | E22: =IFERROR('Historical FS'!E47,0) -> 0.34463984 | F22: =IFERROR('Historical FS'!F47,0) -> 0.053044068 | G22: =IFERROR('Historical FS'!G47,0) -> 0 | H22: =IFERROR('Historical FS'!H47,0) -> 0 | I22: =IFERROR('Historical FS'!I47,0) -> 0 | J22: =IFERROR('Historical FS'!J47,0) -> 0.014606011 | ... L22: =IFERROR('Historical FS'!L47,0) -> 0.017695536 | N22: =IFERROR(AVERAGE(C22:L22),0) -> 0.10889083 | O22: =IFERROR(MEDIAN(C22:M22),0) -> 0.016150773
B23: Return on Equity% | C23: =IFERROR('Historical FS'!C36/(SUM('Historical FS'!C50:C51)),0) -> 0.18784852 | D23: =IFERROR('Historical FS'!D36/(SUM('Historical FS'!D50:D51)),0) -> 0.17621121 | E23: =IFERROR('Historical FS'!E36/(SUM('Historical FS'!E50:E51)),0) -> 0.18186171 | F23: =IFERROR('Historical FS'!F36/(SUM('Historical FS'!F50:F51)),0) -> 0.2018508 | G23: =IFERROR('Historical FS'!G36/(SUM('Historical FS'!G50:G51)),0) -> 0.17906224 | H23: =IFERROR('Historical FS'!H36/(SUM('Historical FS'!H50:H51)),0) -> 0.21764928 | I23: =IFERROR('Historical FS'!I36/(SUM('Historical FS'!I50:I51)),0) -> 0.25130525 | J23: =IFERROR('Historical FS'!J36/(SUM('Historical FS'!J50:J51)),0) -> 0.23381575 | ... L23: =IFERROR('Historical FS'!L36/(SUM('Historical FS'!L50:L51)),0) -> 0.25507859 | N23: =IFERROR(AVERAGE(C23:L23),0) -> 0.21310023 | O23: =IFERROR(MEDIAN(C23:M23),0) -> 0.20975004
B24: Self Sustained Growth Rate | C24: =IFERROR(C22*C23,0) -> 0.063529279 | D24: =IFERROR(D22*D23,0) -> 0.056515974 | E24: =IFERROR(E22*E23,0) -> 0.062676792 | F24: =IFERROR(F22*F23,0) -> 0.010706988 | G24: =IFERROR(G22*G23,0) -> 0 | H24: =IFERROR(H22*H23,0) -> 0 | I24: =IFERROR(I22*I23,0) -> 0 | J24: =IFERROR(J22*J23,0) -> 0.0034151154 | ... L24: =IFERROR(L22*L23,0) -> 0.0045137524 | N24: =IFERROR(AVERAGE(C24:L24),0) -> 0.02013579 | O24: =IFERROR(MEDIAN(C24:M24),0) -> 0.0039644339
B25: Interest Coverage Ratio | C25: =IFERROR('Historical FS'!C27/'Historical FS'!C21,0) -> 291.99918 | D25: =IFERROR('Historical FS'!D27/'Historical FS'!D21,0) -> 132.89549 | E25: =IFERROR('Historical FS'!E27/'Historical FS'!E21,0) -> 240.06695 | F25: =IFERROR('Historical FS'!F27/'Historical FS'!F21,0) -> 217.48132 | G25: =IFERROR('Historical FS'!G27/'Historical FS'!G21,0) -> 265.98568 | H25: =IFERROR('Historical FS'!H27/'Historical FS'!H21,0) -> 314.89815 | I25: =IFERROR('Historical FS'!I27/'Historical FS'!I21,0) -> 307.25537 | J25: =IFERROR('Historical FS'!J27/'Historical FS'!J21,0) -> 605.20276 | ... L25: =IFERROR('Historical FS'!L27/'Historical FS'!L21,0) -> 300.52213 | N25: =IFERROR(AVERAGE(C25:L25),0) -> 321.30416 | O25: =IFERROR(MEDIAN(C25:M25),0) -> 296.26066
B27: Debtor Turnover Ratio | C27: =IFERROR('Historical FS'!C6/'Historical FS'!C62,0) -> 17.284797 | D27: =IFERROR('Historical FS'!D6/'Historical FS'!D62,0) -> 16.19845 | E27: =IFERROR('Historical FS'!E6/'Historical FS'!E62,0) -> 11.979238 | F27: =IFERROR('Historical FS'!F6/'Historical FS'!F62,0) -> 19.273399 | G27: =IFERROR('Historical FS'!G6/'Historical FS'!G62,0) -> 19.689591 | H27: =IFERROR('Historical FS'!H6/'Historical FS'!H62,0) -> 24.633226 | I27: =IFERROR('Historical FS'!I6/'Historical FS'!I62,0) -> 23.990173 | J27: =IFERROR('Historical FS'!J6/'Historical FS'!J62,0) -> 16.874063 | ... L27: =IFERROR('Historical FS'!L6/'Historical FS'!L62,0) -> 20.104821 | N27: =IFERROR(AVERAGE(C27:L27),0) -> 18.598721 | O27: =IFERROR(MEDIAN(C27:M27),0) -> 18.279098
B28: Creditor Turnover Ratio | C28: =IFERROR('Historical FS'!C6/'Historical FS'!C53,0) -> 4.5306245 | D28: =IFERROR('Historical FS'!D6/'Historical FS'!D53,0) -> 3.7152199 | E28: =IFERROR('Historical FS'!E6/'Historical FS'!E53,0) -> 3.8411297 | F28: =IFERROR('Historical FS'!F6/'Historical FS'!F53,0) -> 4.1996201 | G28: =IFERROR('Historical FS'!G6/'Historical FS'!G53,0) -> 3.7479256 | H28: =IFERROR('Historical FS'!H6/'Historical FS'!H53,0) -> 4.1849768 | I28: =IFERROR('Historical FS'!I6/'Historical FS'!I53,0) -> 4.3323459 | J28: =IFERROR('Historical FS'!J6/'Historical FS'!J53,0) -> 4.0093121 | ... L28: =IFERROR('Historical FS'!L6/'Historical FS'!L53,0) -> 4.2106174 | N28: =IFERROR(AVERAGE(C28:L28),0) -> 4.1030189 | O28: =IFERROR(MEDIAN(C28:M28),0) -> 4.1922984
B29: Inventory Turnover | C29: =IFERROR('Historical FS'!C9/'Historical FS'!C63,0) -> 2.7043925 | D29: =IFERROR('Historical FS'!D9/'Historical FS'!D63,0) -> 2.9309188 | E29: =IFERROR('Historical FS'!E9/'Historical FS'!E63,0) -> 3.0810821 | F29: =IFERROR('Historical FS'!F9/'Historical FS'!F63,0) -> 2.7401167 | G29: =IFERROR('Historical FS'!G9/'Historical FS'!G63,0) -> 2.5854666 | H29: =IFERROR('Historical FS'!H9/'Historical FS'!H63,0) -> 3.1344431 | I29: =IFERROR('Historical FS'!I9/'Historical FS'!I63,0) -> 3.253896 | J29: =IFERROR('Historical FS'!J9/'Historical FS'!J63,0) -> 2.5200517 | ... L29: =IFERROR('Historical FS'!L9/'Historical FS'!L63,0) -> 2.301437 | N29: =IFERROR(AVERAGE(C29:L29),0) -> 2.7903702 | O29: =IFERROR(MEDIAN(C29:M29),0) -> 2.7222546
B30: Fixed Asset Turnover | C30: =IFERROR('Historical FS'!C6/'Historical FS'!C56,0) -> 2.6908896 | D30: =IFERROR('Historical FS'!D6/'Historical FS'!D56,0) -> 2.6294508 | E30: =IFERROR('Historical FS'!E6/'Historical FS'!E56,0) -> 2.4950504 | F30: =IFERROR('Historical FS'!F6/'Historical FS'!F56,0) -> 2.2745326 | G30: =IFERROR('Historical FS'!G6/'Historical FS'!G56,0) -> 2.1141916 | H30: =IFERROR('Historical FS'!H6/'Historical FS'!H56,0) -> 2.5027058 | I30: =IFERROR('Historical FS'!I6/'Historical FS'!I56,0) -> 2.743348 | J30: =IFERROR('Historical FS'!J6/'Historical FS'!J56,0) -> 2.4418189 | ... L30: =IFERROR('Historical FS'!L6/'Historical FS'!L56,0) -> 3.5142384 | N30: =IFERROR(AVERAGE(C30:L30),0) -> 2.6837055 | O30: =IFERROR(MEDIAN(C30:M30),0) -> 2.5660783
B31: Capital Turnover Ratio | C31: =IFERROR('Historical FS'!C6/SUM('Historical FS'!C50:C51),0) -> 0.92145874 | D31: =IFERROR('Historical FS'!D6/SUM('Historical FS'!D50:D51),0) -> 0.82743952 | E31: =IFERROR('Historical FS'!E6/SUM('Historical FS'!E50:E51),0) -> 0.81736336 | F31: =IFERROR('Historical FS'!F6/SUM('Historical FS'!F50:F51),0) -> 0.7566299 | G31: =IFERROR('Historical FS'!G6/SUM('Historical FS'!G50:G51),0) -> 0.81623233 | H31: =IFERROR('Historical FS'!H6/SUM('Historical FS'!H50:H51),0) -> 0.97100291 | I31: =IFERROR('Historical FS'!I6/SUM('Historical FS'!I50:I51),0) -> 1.0255045 | J31: =IFERROR('Historical FS'!J6/SUM('Historical FS'!J50:J51),0) -> 0.91175245 | ... L31: =IFERROR('Historical FS'!L6/SUM('Historical FS'!L50:L51),0) -> 1.0877305 | N31: =IFERROR(AVERAGE(C31:L31),0) -> 0.92107002 | O31: =IFERROR(MEDIAN(C31:M31),0) -> 0.9166056
B33: Debtor Days | C33: =IFERROR(365/C27,0) -> 21.116823 | D33: =IFERROR(365/D27,0) -> 22.53302 | E33: =IFERROR(365/E27,0) -> 30.469383 | F33: =IFERROR(365/F27,0) -> 18.938019 | G33: =IFERROR(365/G27,0) -> 18.537714 | H33: =IFERROR(365/H27,0) -> 14.817385 | I33: =IFERROR(365/I27,0) -> 15.214563 | J33: =IFERROR(365/J27,0) -> 21.630831 | ... L33: =IFERROR(365/L27,0) -> 18.154849 | N33: =IFERROR(AVERAGE(C33:L33),0) -> 20.428305 | O33: =IFERROR(MEDIAN(C33:M33),0) -> 20.027421
B34: Payable Days | C34: =IFERROR(365/C28,0) -> 80.562845 | D34: =IFERROR(365/D28,0) -> 98.24452 | E34: =IFERROR(365/E28,0) -> 95.024128 | F34: =IFERROR(365/F28,0) -> 86.912624 | G34: =IFERROR(365/G28,0) -> 97.387204 | H34: =IFERROR(365/H28,0) -> 87.216733 | I34: =IFERROR(365/I28,0) -> 84.249966 | J34: =IFERROR(365/J28,0) -> 91.038061 | ... L34: =IFERROR(365/L28,0) -> 86.685626 | N34: =IFERROR(AVERAGE(C34:L34),0) -> 89.303432 | O34: =IFERROR(MEDIAN(C34:M34),0) -> 87.064678
B35: Inventory Days | C35: =IFERROR(365/C29,0) -> 134.96562 | D35: =IFERROR(365/D29,0) -> 124.53433 | E35: =IFERROR(365/E29,0) -> 118.46487 | F35: =IFERROR(365/F29,0) -> 133.20601 | G35: =IFERROR(365/G29,0) -> 141.17374 | H35: =IFERROR(365/H29,0) -> 116.44812 | I35: =IFERROR(365/I29,0) -> 112.17322 | J35: =IFERROR(365/J29,0) -> 144.8383 | ... L35: =IFERROR(365/L29,0) -> 158.59656 | N35: =IFERROR(AVERAGE(C35:L35),0) -> 132.2038 | O35: =IFERROR(MEDIAN(C35:M35),0) -> 134.08581
B36: Cash Conversion Cycle | C36: =IFERROR(SUM(C33,C35)-C34,0) -> 75.519594 | D36: =IFERROR(SUM(D33,D35)-D34,0) -> 48.822828 | E36: =IFERROR(SUM(E33,E35)-E34,0) -> 53.910127 | F36: =IFERROR(SUM(F33,F35)-F34,0) -> 65.231403 | G36: =IFERROR(SUM(G33,G35)-G34,0) -> 62.324253 | H36: =IFERROR(SUM(H33,H35)-H34,0) -> 44.04877 | I36: =IFERROR(SUM(I33,I35)-I34,0) -> 43.13782 | J36: =IFERROR(SUM(J33,J35)-J34,0) -> 75.431065 | ... L36: =IFERROR(SUM(L33,L35)-L34,0) -> 90.065784 | N36: =IFERROR(AVERAGE(C36:L36),0) -> 63.328678 | O36: =IFERROR(MEDIAN(C36:M36),0) -> 63.777828
B38: CFO/Sales | C38: =IFERROR('Historical FS'!C73/'Historical FS'!C6,0) -> 0.24848974 | D38: =IFERROR('Historical FS'!D73/'Historical FS'!D6,0) -> 0.3031006 | E38: =IFERROR('Historical FS'!E73/'Historical FS'!E6,0) -> 0.26031277 | F38: =IFERROR('Historical FS'!F73/'Historical FS'!F6,0) -> 0.2974356 | G38: =IFERROR('Historical FS'!G73/'Historical FS'!G6,0) -> 0.25431625 | H38: =IFERROR('Historical FS'!H73/'Historical FS'!H6,0) -> 0.26013076 | I38: =IFERROR('Historical FS'!I73/'Historical FS'!I6,0) -> 0.26618455 | J38: =IFERROR('Historical FS'!J73/'Historical FS'!J6,0) -> 0.2528834 | ... L38: =IFERROR('Historical FS'!L73/'Historical FS'!L6,0) -> 0.23411544 | N38: =IFERROR(AVERAGE(C38:L38),0) -> 0.26109874 | O38: =IFERROR(MEDIAN(C38:M38),0) -> 0.2572235
B39: CFO/Total Assets | C39: =IFERROR('Historical FS'!C73/'Historical FS'!C67,0) -> 0.19011859 | D39: =IFERROR('Historical FS'!D73/'Historical FS'!D67,0) -> 0.20500031 | E39: =IFERROR('Historical FS'!E73/'Historical FS'!E67,0) -> 0.17540533 | F39: =IFERROR('Historical FS'!F73/'Historical FS'!F67,0) -> 0.19000799 | G39: =IFERROR('Historical FS'!G73/'Historical FS'!G67,0) -> 0.16983244 | H39: =IFERROR('Historical FS'!H73/'Historical FS'!H67,0) -> 0.20435652 | I39: =IFERROR('Historical FS'!I73/'Historical FS'!I67,0) -> 0.2199387 | J39: =IFERROR('Historical FS'!J73/'Historical FS'!J67,0) -> 0.18722743 | ... L39: =IFERROR('Historical FS'!L73/'Historical FS'!L67,0) -> 0.1971899 | N39: =IFERROR(AVERAGE(C39:L39),0) -> 0.19393783 | O39: =IFERROR(MEDIAN(C39:M39),0) -> 0.19365425
B40: CFO/Total Debt | C40: =IFERROR('Historical FS'!C73/'Historical FS'!C52,0) -> 232.44335 | D40: =IFERROR('Historical FS'!D73/'Historical FS'!D52,0) -> 366.6314 | E40: =IFERROR('Historical FS'!E73/'Historical FS'!E52,0) -> 936.26562 | F40: =IFERROR('Historical FS'!F73/'Historical FS'!F52,0) -> 52.945251 | G40: =IFERROR('Historical FS'!G73/'Historical FS'!G52,0) -> 46.253997 | H40: =IFERROR('Historical FS'!H73/'Historical FS'!H52,0) -> 63.243706 | I40: =IFERROR('Historical FS'!I73/'Historical FS'!I52,0) -> 61.683277 | J40: =IFERROR('Historical FS'!J73/'Historical FS'!J52,0) -> 56.615562 | ... L40: =IFERROR('Historical FS'!L73/'Historical FS'!L52,0) -> 7.696477 | N40: =IFERROR(AVERAGE(C40:L40),0) -> 188.57279 | O40: =IFERROR(MEDIAN(C40:M40),0) -> 61.816264

Sheet Forecasting
B2: ='Data Sheet'!$B$1&" - " & "Sales Forecasting" -> ITC LTD - Sales Forecasting | G2: ='Data Sheet'!$B$1&" - " & "EBIDTA Forecasting" -> ITC LTD - EBIDTA Forecasting | L2: ='Data Sheet'!$B$1&" - "&"EPS Forecasting" -> ITC LTD - EPS Forecasting
B3: Year Weight | C3: Year | D3: ='Historical FS'!B6 -> Sales | E3: Sales Growth | G3: Year Weight | H3: Year | I3: ='Historical FS'!B18 -> EBITDA | J3: EBITDA Growth | L3: Year Weight | M3: Year | N3: ='Historical FS'!B41 -> Earnings per Share | O3: =N3 & " Growth" -> Earnings per Share Growth
B4: 1 | C4: ='Data Sheet'!$B$16 -> 42825 | D4: {=TRANSPOSE('Data Sheet'!B17:K17)} -> 42767.6 | G4: 1 | H4: ='Data Sheet'!$B$16 -> 42825 | I4: {=TRANSPOSE('Data Sheet'!B34:K34)} -> 17040.35 | L4: 1 | M4: ='Data Sheet'!$B$16 -> 42825 | N4: {=TRANSPOSE('Historical FS'!C41:L41)} -> 7.1773384
B5: =B4+1 -> 2 | C5: =C4+365 -> 43190 | D5: 43448.94 | E5: =D5/D4-1 -> 0.015931219 | G5: =G4+1 -> 2 | H5: =H4+365 -> 43190 | I5: 18538.92 | J5: =I5/I4-1 -> 0.087942442 | L5: =L4+1 -> 2 | M5: =M4+365 -> 43190 | N5: 7.5816475 | O5: =N5/N4-1 -> 0.056331341
B6: 3 | C6: =C5+365 -> 43555 | D6: 48339.58 | E6: =D6/D5-1 -> 0.11256063 | G6: 3 | H6: =H5+365 -> 43555 | I6: 20374.26 | J6: =I6/I5-1 -> 0.098999294 | L6: 3 | M6: =M5+365 -> 43555 | N6: 8.7738078 | O6: =N6/N5-1 -> 0.15724291
B7: 4 | C7: =C6+365 -> 43920 | D7: 49387.7 | E7: =D7/D6-1 -> 0.021682439 | G7: 4 | H7: =H6+365 -> 43920 | I7: 21474.31 | J7: =I7/I6-1 -> 0.053992145 | L7: 4 | M7: =M6+365 -> 43920 | N7: 10.718553 | O7: =N7/N6-1 -> 0.22165353
B8: 5 | C8: =C7+365 -> 44285 | D8: 49257.45 | E8: =D8/D7-1 -> -0.0026372963 | G8: 5 | H8: =H7+365 -> 44285 | I8: 19420.04 | J8: =I8/I7-1 -> -0.095661747 | L8: 5 | M8: =M7+365 -> 44285 | N8: 8.779028 | O8: =N8/N7-1 -> -0.18095028
B9: 6 | C9: =C8+365 -> 44650 | D9: 60644.54 | E9: =D9/D8-1 -> 0.23117498 | G9: 6 | H9: =H8+365 -> 44650 | I9: 22272.4 | J9: =I9/I8-1 -> 0.14687714 | L9: 6 | M9: =M8+365 -> 44650 | N9: 11.030657 | O9: =N9/N8-1 -> 0.25647821
B10: 7 | C10: =C9+365 -> 45015 | D10: 70919.03 | E10: =D10/D9-1 -> 0.16942152 | G10: 7 | H10: =H9+365 -> 45015 | I10: 27516.84 | J10: =I10/I9-1 -> 0.23546811 | L10: 7 | M10: =M9+365 -> 45015 | N10: 13.983811 | O10: =N10/N9-1 -> 0.26772234
B11: 8 | C11: =C10+365 -> 45380 | D11: 67931.94 | E11: =D11/D10-1 -> -0.042119724 | G11: 8 | H11: =H10+365 -> 45380 | I11: 28225.4 | J11: =I11/I10-1 -> 0.02575005 | L11: 8 | M11: =M10+365 -> 45380 | N11: 13.953807 | O11: =N11/N10-1 -> -0.0021455732
B12: 9 | C12: =C11+365 -> 45745 | D12: 75323.34 | E12: =D12/D11-1 -> 0.10880596 | G12: 9 | H12: =H11+365 -> 45745 | I12: 43328.48 | J12: =I12/I11-1 -> 0.53508825 | L12: 9 | M12: =M11+365 -> 45745 | N12: 13.784235 | O12: =N12/N11-1 -> -0.012152388
B13: 10 | C13: =C12+365 -> 46110 | D13: 78868.4 | E13: =D13/D12-1 -> 0.047064562 | G13: 10 | H13: =H12+365 -> 46110 | I13: 29500.41 | J13: =I13/I12-1 -> -0.31914505 | L13: 10 | M13: =M12+365 -> 46110 | N13: 14.761212 | O13: =N13/N12-1 -> 0.07087634
B14: 11 | C14: =C13+365 -> 46475 | D14: =FORECAST(B14,$D$3:$D$13,$B$3:$B$13) -> 82754.548 | E14: =D14/D13-1 -> 0.049273828 | G14: 11 | H14: =H13+365 -> 46475 | I14: =FORECAST(G14,$I$3:$I$13,$G$3:$G$13) -> 36299.245 | J14: =I14/I13-1 -> 0.23046577 | L14: 11 | M14: =M13+365 -> 46475 | N14: =FORECAST(L14,$N$3:$N$13,$L$3:$L$13) -> 16.041756 | O14: =N14/N13-1 -> 0.086750603
B15: 12 | C15: =C14+365 -> 46840 | D15: =FORECAST(B15,$D$3:$D$13,$B$3:$B$13) -> 87130.129 | E15: =D15/D14-1 -> 0.052874207 | G15: 12 | H15: =H14+365 -> 46840 | I15: =FORECAST(G15,$I$3:$I$13,$G$3:$G$13) -> 38395.627 | J15: =I15/I14-1 -> 0.057752785 | L15: 12 | M15: =M14+365 -> 46840 | N15: =FORECAST(L15,$N$3:$N$13,$L$3:$L$13) -> 16.948546 | O15: =N15/N14-1 -> 0.056526865
B16: 13 | C16: =C15+365 -> 47205 | D16: =FORECAST(B16,$D$3:$D$13,$B$3:$B$13) -> 91505.71 | E16: =D16/D15-1 -> 0.050218921 | G16: 13 | H16: =H15+365 -> 47205 | I16: =FORECAST(G16,$I$3:$I$13,$G$3:$G$13) -> 40492.01 | J16: =I16/I15-1 -> 0.054599511 | L16: 13 | M16: =M15+365 -> 47205 | N16: =FORECAST(L16,$N$3:$N$13,$L$3:$L$13) -> 17.855336 | O16: =N16/N15-1 -> 0.053502534
B17: 14 | C17: =C16+365 -> 47570 | D17: =FORECAST(B17,$D$3:$D$13,$B$3:$B$13) -> 95881.291 | E17: =D17/D16-1 -> 0.047817574 | G17: 14 | H17: =H16+365 -> 47570 | I17: =FORECAST(G17,$I$3:$I$13,$G$3:$G$13) -> 42588.392 | J17: =I17/I16-1 -> 0.051772745 | L17: 14 | M17: =M16+365 -> 47570 | N17: =FORECAST(L17,$N$3:$N$13,$L$3:$L$13) -> 18.762126 | O17: =N17/N16-1 -> 0.050785387
B18: 15 | C18: =C17+365 -> 47935 | D18: =FORECAST(B18,$D$3:$D$13,$B$3:$B$13) -> 100256.87 | E18: =D18/D17-1 -> 0.0456354 | G18: 15 | H18: =H17+365 -> 47935 | I18: =FORECAST(G18,$I$3:$I$13,$G$3:$G$13) -> 44684.775 | J18: =I18/I17-1 -> 0.049224269 | L18: 15 | M18: =M17+365 -> 47935 | N18: =FORECAST(L18,$N$3:$N$13,$L$3:$L$13) -> 19.668916 | O18: =N18/N17-1 -> 0.048330885
B20: Metric | C20: FY17 | D20: FY26 | E20: CAGR
B21: Sales | C21: =D4 -> 42767.6 | D21: =D13 -> 78868.4 | E21: =(D21/C21)^(1/9)-1 -> 0.070365289
B22: EBITDA | C22: =I4 -> 17040.35 | D22: =I13 -> 29500.41 | E22: =(D22/C22)^(1/9)-1 -> 0.062877668
B23: EBIT | C23: ='Historical FS'!C27 -> 14316.72 | D23: ='Historical FS'!L27 -> 25595.47 | E23: =(D23/C23)^(1/9)-1 -> 0.066683331
B24: Net Profit | C24: ='Historical FS'!C36 -> 8718.6 | D24: ='Historical FS'!L36 -> 18495.06 | E24: =(D24/C24)^(1/9)-1 -> 0.087151046
B25: EPS | C25: =N4 -> 7.1773384 | D25: =N13 -> 14.761212 | E25: =(D25/C25)^(1/9)-1 -> 0.083416382

Sheet Data Sheet
A1: COMPANY NAME | B1: ITC LTD
A2: LATEST VERSION | B2: 2.1 | E2: PLEASE DO NOT MAKE ANY CHANGES TO THIS SHEET
A3: CURRENT VERSION | B3: 2.1
A5: META
A6: Number of shares | B6: =IF(B9>0, B9/B8, 0) -> 1251.1206
A7: Face Value | B7: 1
A8: Current Price | B8: 269
A9: Market Capitalization | B9: 336551.44
A15: PROFIT & LOSS | B15: =B26+B34 -> 18193.14 | K15: =K17-K18-K20-K21-K22-K23-K19 -> 24529.96
A16: Report Date | B16: 42825 | C16: 43190 | D16: 43555 | E16: 43921 | F16: 44286 | G16: 44651 | H16: 45016 | I16: 45382 | J16: 45747 | K16: 46112
A17: Sales | B17: 42767.6 | C17: 43448.94 | D17: 48339.58 | E17: 49387.7 | F17: 49257.45 | G17: 60644.54 | H17: 70919.03 | I17: 67931.94 | J17: 75323.34 | K17: 78868.4
A18: Raw Material Cost | B18: 15456.59 | C18: 14827.72 | D18: 17623.52 | E18: 18048.6 | F18: 20776.71 | G18: 27071.07 | H18: 29364.36 | I18: 27348.57 | J18: 32704.37 | K18: 35098.34
A19: Change in Inventory | B19: -592.57 | C19: -1027.76 | D19: 203.19 | E19: 703.13 | F19: 645.27 | G19: 686 | H19: 358.59 | I19: 367.77 | J19: 725.65 | K19: 2550.46
A20: Power and Fuel | B20: 584.33 | C20: 653.5 | D20: 746.73 | E20: 780.85 | F20: 699.56 | G20: 889.77 | H20: 1232.34 | I20: 952.9 | J20: 975.35 | K20: 947.71
A21: Other Mfr. Exp | B21: 1683.9 | C21: 1697.62 | D21: 1871.01 | E21: 1908.29 | F21: 1587.18 | G21: 1887.67 | H21: 2327.8 | I21: 2183.76 | J21: 2345.36 | K21: 2582.48
A22: Employee Cost | B22: 3631.73 | C22: 3760.9 | D22: 4177.88 | E22: 4295.79 | F22: 4463.33 | G22: 4890.55 | H22: 5736.22 | I22: 5548.53 | J22: 6169.78 | K22: 6781.5
A23: Selling and admin | B23: 4179.74 | C23: 3954.87 | D23: 4546.39 | E23: 4488.63 | F23: 4236.77 | G23: 4858.38 | H23: 5604.08 | I23: 5312.45 | J23: 5793.29 | K23: 6377.95
A24: Other Expenses | B24: 1169.23 | C24: 1005.98 | D24: 1039.85 | E24: 1225.13 | F24: 1074.39 | G24: 1109.95 | H24: 1308.56 | I24: 1765.97 | J24: 2229.26 | K24: 2324.88
A25: Other Income | B25: 1758.63 | C25: 2239.81 | D25: 2080.44 | E25: 2417.32 | F25: 2576.95 | G25: 1909.72 | H25: 2097.64 | I25: 3330.45 | J25: 17802.75 | K25: 2523.09
A26: Depreciation | B26: 1152.79 | C26: 1236.28 | D26: 1396.61 | E26: 1644.91 | F26: 1645.59 | G26: 1732.41 | H26: 1809.01 | I26: 1518.05 | J26: 1646.32 | K26: 1710.53
A27: Interest | B27: 49.03 | C27: 115.01 | D27: 71.4 | E27: 81.38 | F27: 57.97 | G27: 59.99 | H27: 77.77 | I27: 39.11 | J27: 45.06 | K27: 85.17
... A31: Dividend Amount | B31: 5770.02 | C31: 6285.21 | D31: 7048.7 | E31: 12476.58 | F31: 13231.96 | G31: 14171.8 | H31: 19263.4 | I31: 17166.46 | J31: 17957.73 | K31: 18167.78
